[2024-10-21T23:02:34.278+0000] {taskinstance.py:1083} INFO - Dependencies all met for <TaskInstance: DAG_Data_Preprocessing.load_data_task manual__2024-10-21T23:02:25.371781+00:00 [queued]>
[2024-10-21T23:02:34.302+0000] {taskinstance.py:1083} INFO - Dependencies all met for <TaskInstance: DAG_Data_Preprocessing.load_data_task manual__2024-10-21T23:02:25.371781+00:00 [queued]>
[2024-10-21T23:02:34.303+0000] {taskinstance.py:1279} INFO - 
--------------------------------------------------------------------------------
[2024-10-21T23:02:34.304+0000] {taskinstance.py:1280} INFO - Starting attempt 1 of 1
[2024-10-21T23:02:34.305+0000] {taskinstance.py:1281} INFO - 
--------------------------------------------------------------------------------
[2024-10-21T23:02:34.325+0000] {taskinstance.py:1300} INFO - Executing <Task(PythonOperator): load_data_task> on 2024-10-21 23:02:25.371781+00:00
[2024-10-21T23:02:34.352+0000] {standard_task_runner.py:55} INFO - Started process 238 to run task
[2024-10-21T23:02:34.358+0000] {standard_task_runner.py:82} INFO - Running: ['***', 'tasks', 'run', 'DAG_Data_Preprocessing', 'load_data_task', 'manual__2024-10-21T23:02:25.371781+00:00', '--job-id', '40', '--raw', '--subdir', 'DAGS_FOLDER/***dag.py', '--cfg-path', '/tmp/tmpod8_r26v']
[2024-10-21T23:02:34.360+0000] {standard_task_runner.py:83} INFO - Job 40: Subtask load_data_task
[2024-10-21T23:02:34.448+0000] {task_command.py:388} INFO - Running <TaskInstance: DAG_Data_Preprocessing.load_data_task manual__2024-10-21T23:02:25.371781+00:00 [running]> on host 38c00b4e6cbc
[2024-10-21T23:02:34.548+0000] {taskinstance.py:1509} INFO - Exporting the following env vars:
AIRFLOW_CTX_DAG_OWNER=Krishna
AIRFLOW_CTX_DAG_ID=DAG_Data_Preprocessing
AIRFLOW_CTX_TASK_ID=load_data_task
AIRFLOW_CTX_EXECUTION_DATE=2024-10-21T23:02:25.371781+00:00
AIRFLOW_CTX_TRY_NUMBER=1
AIRFLOW_CTX_DAG_RUN_ID=manual__2024-10-21T23:02:25.371781+00:00
[2024-10-21T23:02:34.611+0000] {taskinstance.py:1768} ERROR - Task failed with exception
Traceback (most recent call last):
  File "/home/airflow/.local/lib/python3.7/site-packages/airflow/operators/python.py", line 175, in execute
    return_value = self.execute_callable()
  File "/home/airflow/.local/lib/python3.7/site-packages/airflow/operators/python.py", line 192, in execute_callable
    return self.python_callable(*self.op_args, **self.op_kwargs)
  File "/opt/airflow/dags/airflowdag.py", line 30, in load_data_callable
    kwargs['ti'].xcom_push(key='data', value=data)
  File "/home/airflow/.local/lib/python3.7/site-packages/airflow/utils/session.py", line 75, in wrapper
    return func(*args, session=session, **kwargs)
  File "/home/airflow/.local/lib/python3.7/site-packages/airflow/models/taskinstance.py", line 2297, in xcom_push
    session=session,
  File "/home/airflow/.local/lib/python3.7/site-packages/airflow/utils/session.py", line 72, in wrapper
    return func(*args, **kwargs)
  File "/home/airflow/.local/lib/python3.7/site-packages/airflow/models/xcom.py", line 240, in set
    map_index=map_index,
  File "/home/airflow/.local/lib/python3.7/site-packages/airflow/models/xcom.py", line 627, in serialize_value
    return json.dumps(value, cls=XComEncoder).encode("UTF-8")
  File "/usr/local/lib/python3.7/json/__init__.py", line 238, in dumps
    **kw).encode(obj)
  File "/home/airflow/.local/lib/python3.7/site-packages/airflow/utils/json.py", line 176, in encode
    return super().encode(o)
  File "/usr/local/lib/python3.7/json/encoder.py", line 199, in encode
    chunks = self.iterencode(o, _one_shot=True)
  File "/usr/local/lib/python3.7/json/encoder.py", line 257, in iterencode
    return _iterencode(o, 0)
  File "/home/airflow/.local/lib/python3.7/site-packages/airflow/utils/json.py", line 153, in default
    CLASSNAME: o.__module__ + "." + o.__class__.__qualname__,
AttributeError: 'bytes' object has no attribute '__module__'
[2024-10-21T23:02:34.636+0000] {taskinstance.py:1323} INFO - Marking task as FAILED. dag_id=DAG_Data_Preprocessing, task_id=load_data_task, execution_date=20241021T230225, start_date=20241021T230234, end_date=20241021T230234
[2024-10-21T23:02:34.657+0000] {standard_task_runner.py:105} ERROR - Failed to execute job 40 for task load_data_task ('bytes' object has no attribute '__module__'; 238)
[2024-10-21T23:02:34.692+0000] {local_task_job.py:208} INFO - Task exited with return code 1
[2024-10-21T23:02:34.720+0000] {taskinstance.py:2578} INFO - 0 downstream tasks scheduled from follow-on schedule check
