[2024-11-03T05:17:40.782+0000] {taskinstance.py:1083} INFO - Dependencies all met for <TaskInstance: DAG_Data_Preprocessing.load_data_task manual__2024-11-03T05:17:36.665262+00:00 [queued]>
[2024-11-03T05:17:40.793+0000] {taskinstance.py:1083} INFO - Dependencies all met for <TaskInstance: DAG_Data_Preprocessing.load_data_task manual__2024-11-03T05:17:36.665262+00:00 [queued]>
[2024-11-03T05:17:40.793+0000] {taskinstance.py:1279} INFO - 
--------------------------------------------------------------------------------
[2024-11-03T05:17:40.793+0000] {taskinstance.py:1280} INFO - Starting attempt 1 of 1
[2024-11-03T05:17:40.794+0000] {taskinstance.py:1281} INFO - 
--------------------------------------------------------------------------------
[2024-11-03T05:17:40.808+0000] {taskinstance.py:1300} INFO - Executing <Task(PythonOperator): load_data_task> on 2024-11-03 05:17:36.665262+00:00
[2024-11-03T05:17:40.814+0000] {standard_task_runner.py:55} INFO - Started process 157 to run task
[2024-11-03T05:17:40.817+0000] {standard_task_runner.py:82} INFO - Running: ['***', 'tasks', 'run', 'DAG_Data_Preprocessing', 'load_data_task', 'manual__2024-11-03T05:17:36.665262+00:00', '--job-id', '23', '--raw', '--subdir', 'DAGS_FOLDER/***dag.py', '--cfg-path', '/tmp/tmpxg30okvn']
[2024-11-03T05:17:40.820+0000] {standard_task_runner.py:83} INFO - Job 23: Subtask load_data_task
[2024-11-03T05:17:40.896+0000] {task_command.py:388} INFO - Running <TaskInstance: DAG_Data_Preprocessing.load_data_task manual__2024-11-03T05:17:36.665262+00:00 [running]> on host a95df74735a7
[2024-11-03T05:17:40.975+0000] {taskinstance.py:1509} INFO - Exporting the following env vars:
AIRFLOW_CTX_DAG_OWNER=House_Price_Prediction Team
AIRFLOW_CTX_DAG_ID=DAG_Data_Preprocessing
AIRFLOW_CTX_TASK_ID=load_data_task
AIRFLOW_CTX_EXECUTION_DATE=2024-11-03T05:17:36.665262+00:00
AIRFLOW_CTX_TRY_NUMBER=1
AIRFLOW_CTX_DAG_RUN_ID=manual__2024-11-03T05:17:36.665262+00:00
[2024-11-03T05:17:40.987+0000] {taskinstance.py:1768} ERROR - Task failed with exception
Traceback (most recent call last):
  File "/home/airflow/.local/lib/python3.7/site-packages/airflow/operators/python.py", line 175, in execute
    return_value = self.execute_callable()
  File "/home/airflow/.local/lib/python3.7/site-packages/airflow/operators/python.py", line 192, in execute_callable
    return self.python_callable(*self.op_args, **self.op_kwargs)
  File "/opt/airflow/dags/airflowdag.py", line 30, in load_data_callable
    data = load_data()
  File "/opt/airflow/dags/src/data_prep.py", line 16, in load_data
    gcp_credentials = Variable.get("GOOGLE_APPLICATION_CREDENTIALS", deserialize_json=True)
  File "/home/airflow/.local/lib/python3.7/site-packages/airflow/models/variable.py", line 141, in get
    raise KeyError(f"Variable {key} does not exist")
KeyError: 'Variable GOOGLE_APPLICATION_CREDENTIALS does not exist'
[2024-11-03T05:17:40.999+0000] {taskinstance.py:1323} INFO - Marking task as FAILED. dag_id=DAG_Data_Preprocessing, task_id=load_data_task, execution_date=20241103T051736, start_date=20241103T051740, end_date=20241103T051740
[2024-11-03T05:17:41.013+0000] {standard_task_runner.py:105} ERROR - Failed to execute job 23 for task load_data_task ('Variable GOOGLE_APPLICATION_CREDENTIALS does not exist'; 157)
[2024-11-03T05:17:41.038+0000] {local_task_job.py:208} INFO - Task exited with return code 1
[2024-11-03T05:17:41.068+0000] {taskinstance.py:2578} INFO - 0 downstream tasks scheduled from follow-on schedule check
