[2024-10-29T15:51:23.031+0000] {taskinstance.py:1083} INFO - Dependencies all met for <TaskInstance: DAG_Data_Preprocessing.load_model_task manual__2024-10-29T15:41:56.373924+00:00 [queued]>
[2024-10-29T15:51:23.052+0000] {taskinstance.py:1083} INFO - Dependencies all met for <TaskInstance: DAG_Data_Preprocessing.load_model_task manual__2024-10-29T15:41:56.373924+00:00 [queued]>
[2024-10-29T15:51:23.053+0000] {taskinstance.py:1279} INFO - 
--------------------------------------------------------------------------------
[2024-10-29T15:51:23.053+0000] {taskinstance.py:1280} INFO - Starting attempt 1 of 1
[2024-10-29T15:51:23.054+0000] {taskinstance.py:1281} INFO - 
--------------------------------------------------------------------------------
[2024-10-29T15:51:23.080+0000] {taskinstance.py:1300} INFO - Executing <Task(PythonOperator): load_model_task> on 2024-10-29 15:41:56.373924+00:00
[2024-10-29T15:51:23.100+0000] {standard_task_runner.py:55} INFO - Started process 1091 to run task
[2024-10-29T15:51:23.109+0000] {standard_task_runner.py:82} INFO - Running: ['***', 'tasks', 'run', 'DAG_Data_Preprocessing', 'load_model_task', 'manual__2024-10-29T15:41:56.373924+00:00', '--job-id', '72', '--raw', '--subdir', 'DAGS_FOLDER/***dag.py', '--cfg-path', '/tmp/tmpbxj8_iym']
[2024-10-29T15:51:23.113+0000] {standard_task_runner.py:83} INFO - Job 72: Subtask load_model_task
[2024-10-29T15:51:23.215+0000] {task_command.py:388} INFO - Running <TaskInstance: DAG_Data_Preprocessing.load_model_task manual__2024-10-29T15:41:56.373924+00:00 [running]> on host 4cb9a01d4387
[2024-10-29T15:51:23.315+0000] {taskinstance.py:1509} INFO - Exporting the following env vars:
AIRFLOW_CTX_DAG_OWNER=Krishna
AIRFLOW_CTX_DAG_ID=DAG_Data_Preprocessing
AIRFLOW_CTX_TASK_ID=load_model_task
AIRFLOW_CTX_EXECUTION_DATE=2024-10-29T15:41:56.373924+00:00
AIRFLOW_CTX_TRY_NUMBER=1
AIRFLOW_CTX_DAG_RUN_ID=manual__2024-10-29T15:41:56.373924+00:00
[2024-10-29T15:51:23.360+0000] {taskinstance.py:1768} ERROR - Task failed with exception
Traceback (most recent call last):
  File "/home/airflow/.local/lib/python3.7/site-packages/airflow/operators/python.py", line 175, in execute
    return_value = self.execute_callable()
  File "/home/airflow/.local/lib/python3.7/site-packages/airflow/operators/python.py", line 192, in execute_callable
    return self.python_callable(*self.op_args, **self.op_kwargs)
  File "/opt/airflow/dags/airflowdag.py", line 72, in load_model_callable
    load_model_elbow("model.sav", build_model_output)
  File "/opt/airflow/dags/src/data_prep.py", line 89, in load_model_elbow
    range(1, 50), sse, curve="convex", direction="decreasing"
  File "/home/airflow/.local/lib/python3.7/site-packages/kneed/knee_locator.py", line 171, in __init__
    uspline = interpolate.interp1d(self.x, self.y)
  File "/home/airflow/.local/lib/python3.7/site-packages/scipy/interpolate/interpolate.py", line 436, in __init__
    _Interpolator1D.__init__(self, x, y, axis=axis)
  File "/home/airflow/.local/lib/python3.7/site-packages/scipy/interpolate/polyint.py", line 54, in __init__
    self._set_yi(yi, xi=xi, axis=axis)
  File "/home/airflow/.local/lib/python3.7/site-packages/scipy/interpolate/polyint.py", line 124, in _set_yi
    raise ValueError("x and y arrays must be equal in length along "
ValueError: x and y arrays must be equal in length along interpolation axis.
[2024-10-29T15:51:23.387+0000] {taskinstance.py:1323} INFO - Marking task as FAILED. dag_id=DAG_Data_Preprocessing, task_id=load_model_task, execution_date=20241029T154156, start_date=20241029T155123, end_date=20241029T155123
[2024-10-29T15:51:23.410+0000] {standard_task_runner.py:105} ERROR - Failed to execute job 72 for task load_model_task (x and y arrays must be equal in length along interpolation axis.; 1091)
[2024-10-29T15:51:23.442+0000] {local_task_job.py:208} INFO - Task exited with return code 1
[2024-10-29T15:51:23.462+0000] {taskinstance.py:2578} INFO - 0 downstream tasks scheduled from follow-on schedule check
