[2024-10-21T22:55:21.602+0000] {taskinstance.py:1083} INFO - Dependencies all met for <TaskInstance: DAG_Data_Preprocessing.load_data_task manual__2024-10-21T22:55:13.002613+00:00 [queued]>
[2024-10-21T22:55:21.626+0000] {taskinstance.py:1083} INFO - Dependencies all met for <TaskInstance: DAG_Data_Preprocessing.load_data_task manual__2024-10-21T22:55:13.002613+00:00 [queued]>
[2024-10-21T22:55:21.626+0000] {taskinstance.py:1279} INFO - 
--------------------------------------------------------------------------------
[2024-10-21T22:55:21.627+0000] {taskinstance.py:1280} INFO - Starting attempt 1 of 1
[2024-10-21T22:55:21.628+0000] {taskinstance.py:1281} INFO - 
--------------------------------------------------------------------------------
[2024-10-21T22:55:21.644+0000] {taskinstance.py:1300} INFO - Executing <Task(PythonOperator): load_data_task> on 2024-10-21 22:55:13.002613+00:00
[2024-10-21T22:55:21.653+0000] {standard_task_runner.py:55} INFO - Started process 265 to run task
[2024-10-21T22:55:21.657+0000] {standard_task_runner.py:82} INFO - Running: ['***', 'tasks', 'run', 'DAG_Data_Preprocessing', 'load_data_task', 'manual__2024-10-21T22:55:13.002613+00:00', '--job-id', '37', '--raw', '--subdir', 'DAGS_FOLDER/***dag.py', '--cfg-path', '/tmp/tmp5fbu69p2']
[2024-10-21T22:55:21.659+0000] {standard_task_runner.py:83} INFO - Job 37: Subtask load_data_task
[2024-10-21T22:55:21.729+0000] {task_command.py:388} INFO - Running <TaskInstance: DAG_Data_Preprocessing.load_data_task manual__2024-10-21T22:55:13.002613+00:00 [running]> on host 38c00b4e6cbc
[2024-10-21T22:55:21.809+0000] {taskinstance.py:1509} INFO - Exporting the following env vars:
AIRFLOW_CTX_DAG_OWNER=Krishna
AIRFLOW_CTX_DAG_ID=DAG_Data_Preprocessing
AIRFLOW_CTX_TASK_ID=load_data_task
AIRFLOW_CTX_EXECUTION_DATE=2024-10-21T22:55:13.002613+00:00
AIRFLOW_CTX_TRY_NUMBER=1
AIRFLOW_CTX_DAG_RUN_ID=manual__2024-10-21T22:55:13.002613+00:00
[2024-10-21T22:55:21.814+0000] {taskinstance.py:1768} ERROR - Task failed with exception
Traceback (most recent call last):
  File "/home/airflow/.local/lib/python3.7/site-packages/airflow/operators/python.py", line 175, in execute
    return_value = self.execute_callable()
  File "/home/airflow/.local/lib/python3.7/site-packages/airflow/operators/python.py", line 192, in execute_callable
    return self.python_callable(*self.op_args, **self.op_kwargs)
  File "/opt/airflow/dags/airflowdag.py", line 28, in load_data_callable
    data = load_data()
  File "/opt/airflow/dags/src/data_prep.py", line 17, in load_data
    df = pd.read_csv(os.path.join(os.path.dirname(__file__), "../data/file.csv"))
  File "/home/airflow/.local/lib/python3.7/site-packages/pandas/util/_decorators.py", line 311, in wrapper
    return func(*args, **kwargs)
  File "/home/airflow/.local/lib/python3.7/site-packages/pandas/io/parsers/readers.py", line 586, in read_csv
    return _read(filepath_or_buffer, kwds)
  File "/home/airflow/.local/lib/python3.7/site-packages/pandas/io/parsers/readers.py", line 482, in _read
    parser = TextFileReader(filepath_or_buffer, **kwds)
  File "/home/airflow/.local/lib/python3.7/site-packages/pandas/io/parsers/readers.py", line 811, in __init__
    self._engine = self._make_engine(self.engine)
  File "/home/airflow/.local/lib/python3.7/site-packages/pandas/io/parsers/readers.py", line 1040, in _make_engine
    return mapping[engine](self.f, **self.options)  # type: ignore[call-arg]
  File "/home/airflow/.local/lib/python3.7/site-packages/pandas/io/parsers/c_parser_wrapper.py", line 51, in __init__
    self._open_handles(src, kwds)
  File "/home/airflow/.local/lib/python3.7/site-packages/pandas/io/parsers/base_parser.py", line 229, in _open_handles
    errors=kwds.get("encoding_errors", "strict"),
  File "/home/airflow/.local/lib/python3.7/site-packages/pandas/io/common.py", line 707, in get_handle
    newline="",
FileNotFoundError: [Errno 2] No such file or directory: '/opt/airflow/dags/src/../data/file.csv'
[2024-10-21T22:55:21.842+0000] {taskinstance.py:1323} INFO - Marking task as FAILED. dag_id=DAG_Data_Preprocessing, task_id=load_data_task, execution_date=20241021T225513, start_date=20241021T225521, end_date=20241021T225521
[2024-10-21T22:55:21.863+0000] {standard_task_runner.py:105} ERROR - Failed to execute job 37 for task load_data_task ([Errno 2] No such file or directory: '/opt/airflow/dags/src/../data/file.csv'; 265)
[2024-10-21T22:55:21.910+0000] {local_task_job.py:208} INFO - Task exited with return code 1
[2024-10-21T22:55:21.946+0000] {taskinstance.py:2578} INFO - 0 downstream tasks scheduled from follow-on schedule check
