[2024-11-03T05:27:21.891+0000] {taskinstance.py:1083} INFO - Dependencies all met for <TaskInstance: DAG_Data_Preprocessing.load_data_task manual__2024-11-03T05:27:19.394371+00:00 [queued]>
[2024-11-03T05:27:21.908+0000] {taskinstance.py:1083} INFO - Dependencies all met for <TaskInstance: DAG_Data_Preprocessing.load_data_task manual__2024-11-03T05:27:19.394371+00:00 [queued]>
[2024-11-03T05:27:21.908+0000] {taskinstance.py:1279} INFO - 
--------------------------------------------------------------------------------
[2024-11-03T05:27:21.909+0000] {taskinstance.py:1280} INFO - Starting attempt 1 of 1
[2024-11-03T05:27:21.909+0000] {taskinstance.py:1281} INFO - 
--------------------------------------------------------------------------------
[2024-11-03T05:27:21.934+0000] {taskinstance.py:1300} INFO - Executing <Task(PythonOperator): load_data_task> on 2024-11-03 05:27:19.394371+00:00
[2024-11-03T05:27:21.943+0000] {standard_task_runner.py:55} INFO - Started process 190 to run task
[2024-11-03T05:27:21.948+0000] {standard_task_runner.py:82} INFO - Running: ['***', 'tasks', 'run', 'DAG_Data_Preprocessing', 'load_data_task', 'manual__2024-11-03T05:27:19.394371+00:00', '--job-id', '29', '--raw', '--subdir', 'DAGS_FOLDER/***dag.py', '--cfg-path', '/tmp/tmpanq5fk75']
[2024-11-03T05:27:21.951+0000] {standard_task_runner.py:83} INFO - Job 29: Subtask load_data_task
[2024-11-03T05:27:22.051+0000] {task_command.py:388} INFO - Running <TaskInstance: DAG_Data_Preprocessing.load_data_task manual__2024-11-03T05:27:19.394371+00:00 [running]> on host a95df74735a7
[2024-11-03T05:27:22.177+0000] {taskinstance.py:1509} INFO - Exporting the following env vars:
AIRFLOW_CTX_DAG_OWNER=House_Price_Prediction Team
AIRFLOW_CTX_DAG_ID=DAG_Data_Preprocessing
AIRFLOW_CTX_TASK_ID=load_data_task
AIRFLOW_CTX_EXECUTION_DATE=2024-11-03T05:27:19.394371+00:00
AIRFLOW_CTX_TRY_NUMBER=1
AIRFLOW_CTX_DAG_RUN_ID=manual__2024-11-03T05:27:19.394371+00:00
[2024-11-03T05:27:22.192+0000] {taskinstance.py:1768} ERROR - Task failed with exception
Traceback (most recent call last):
  File "/home/airflow/.local/lib/python3.7/site-packages/airflow/operators/python.py", line 175, in execute
    return_value = self.execute_callable()
  File "/home/airflow/.local/lib/python3.7/site-packages/airflow/operators/python.py", line 192, in execute_callable
    return self.python_callable(*self.op_args, **self.op_kwargs)
  File "/opt/airflow/dags/airflowdag.py", line 30, in load_data_callable
    data = load_data()
  File "/opt/airflow/dags/src/data_prep.py", line 16, in load_data
    gcp_credentials = Variable.get("GOOGLE_APPLICATION_CREDENTIALS", deserialize_json=True)
  File "/home/airflow/.local/lib/python3.7/site-packages/airflow/models/variable.py", line 141, in get
    raise KeyError(f"Variable {key} does not exist")
KeyError: 'Variable GOOGLE_APPLICATION_CREDENTIALS does not exist'
[2024-11-03T05:27:22.208+0000] {taskinstance.py:1323} INFO - Marking task as FAILED. dag_id=DAG_Data_Preprocessing, task_id=load_data_task, execution_date=20241103T052719, start_date=20241103T052721, end_date=20241103T052722
[2024-11-03T05:27:22.224+0000] {standard_task_runner.py:105} ERROR - Failed to execute job 29 for task load_data_task ('Variable GOOGLE_APPLICATION_CREDENTIALS does not exist'; 190)
[2024-11-03T05:27:22.249+0000] {local_task_job.py:208} INFO - Task exited with return code 1
[2024-11-03T05:27:22.289+0000] {taskinstance.py:2578} INFO - 0 downstream tasks scheduled from follow-on schedule check
